Workbook

Sheet 00_README
B2: AI Concierge for Luxury Hotels — MVP Financial Model
B3: All inputs are blue. Change one and every downstream number updates.
B5: PURPOSE | C5: Answers three questions. (1) Does a single property make money at every size? (2) How many properties are needed to break even? (3) How much cash is required before that point?
B6: HOW TO USE | C6: 01_Assumptions — global costs and commercial rates. 02_Property_Sizes — the five archetypes (rooms, engagement, price, mix). 03_Unit_Economics — per-property P&L, payback and LTV, computed live. 04_Messaging_Costs — WhatsApp cost by market. 05_Ramp — 24-month model for three scenarios. 06_Scenarios — side-by-side outcome. 07_Sensitivity — where the model breaks. 08_Cash_Runway — funding requirement.
B7: LEGEND | C7: Blue text on amber = input. Black = formula. Green = headline output.
B8: THE CORE INSIGHT | C8: Revenue steps up with rooms, but cost is driven by conversations — and conversations per room FALL as properties grow (small properties message far more per key). Gross margin is therefore weakest at the small end and strongest at the large end, while onboarding labour per property is highest at the large end. The price curve is built to reflect exactly that.
B9: CONVENTIONS | C9: A conversation is one guest thread, not one message. 'Business messages' = what the hotel sends. WhatsApp fees apply per delivered business message after 1,000 free service messages per number per month (Meta, effective 1 Oct 2026). Gross margin includes support labour — deliberately conservative. All values USD, pre-tax, pre-dilution.
B10: EXCLUDED | C10: Income tax, VAT, equity raised, FX movement, bad debt.
B12: HEADLINE OUTPUTS (live)
B13: Blended gross margin | C13: ='03_Unit_Economics'!O12 -> 0.8457151
B14: Blended gross profit / property / month | C14: ='01_Assumptions'!C43 -> 371.69179
B15: Properties needed to cover fixed opex | C15: ='07_Sensitivity'!C28 -> 19.370888
B16: Base-case MRR, month 24 | C16: ='06_Scenarios'!D9 -> 13624.5
B17: Base-case peak funding requirement | C17: =ABS('06_Scenarios'!D16) -> 63960.972
B18: Conservative peak funding requirement | C18: =ABS('06_Scenarios'!C16) -> 80866.835

Sheet 01_Assumptions
B2: Global assumptions
B3: Single source of truth for every cost and commercial rate.
B5: COST OF SERVICE
B6: Support / success labour rate | C6: 32 | D6: $/hour | E6: Blended contractor rate
B7: Onboarding labour rate | C7: 32 | D7: $/hour | E7: Costs setup against the setup fee
B8: Fallback support hours / property / month | C8: 1.3 | D8: hours | E8: Overridden per tier on 02
B9: Payment processing | C9: 0.029 | D9: % of revenue | E9: Card fees on subscription revenue
B11: INFRASTRUCTURE
B12: Fixed infra pool | C12: 260 | D12: $/month | E12: Supabase Pro + compute, Vercel Pro, Resend, Sentry
B13: Properties the pool is allocated over | C13: 25 | D13: properties | E13: Pool / N = per-property infra COGS
B14: Per-property variable infra | C14: 1.5 | D14: $/month | E14: Storage, bandwidth, embedding storage
B16: AI COSTS
B17: LLM input price | C17: 0.1 | D17: $ / 1M tokens | E17: Current small-model tier; not a margin driver
B18: LLM output price | C18: 0.5 | D18: $ / 1M tokens
B19: Input tokens / conversation | C19: 18000 | D19: tokens | E19: ~5 turns with RAG context, history, facts block
B20: Output tokens / conversation | C20: 700 | D20: tokens | E20: Luxury tone runs slightly longer
B21: Aux AI / conversation | C21: 0.002 | D21: $/conversation | E21: Escalation classifier, intent + sentiment, summaries
B23: MESSAGING
B24: BSP markup on WhatsApp | C24: 0.2 | D24: % on Meta fee | E24: Passed through to the hotel at cost + markup
B25: Free service messages / number / month | C25: 1000 | D25: messages | E25: Meta allowance; resets monthly, no rollover
B26: Business messages / conversation | C26: 5 | D26: messages | E26: Hotel-sent replies per thread
B28: COMMERCIAL
B29: Setup fee (one-time) | C29: 500 | D29: $ | E29: Per property
B30: Setup fee waived / discounted share | C30: 0.5 | D30: % | E30: Design partners + negotiation room
B31: Monthly gross churn (paid) | C31: 0.025 | D31: % | E31: 26% annualised; stress-tested on 07
B32: Pilot → paid conversion | C32: 0.6 | D32: % | E32: Within ~1 month of going live
B33: Blended CAC | C33: 900 | D33: $ | E33: Founder-led outbound, content, demo time
B35: RAMP AND OPEX
B36: Fixed opex, base | C36: 7200 | D36: $/month | E36: Founder draw 4,500 + tools 400 + marketing 800 + contractor 1,500
B37: Opex step (support hire) | C37: 3600 | D37: $/month | E37: Added at each threshold
B38: Step threshold 1 (active properties) | C38: 25 | D38: properties
B39: Step threshold 2 (active properties) | C39: 55 | D39: properties
B40: Pre-launch capital (weeks 1-6) | C40: 17000 | D40: $ | E40: 1.5 months opex + legal/DPA/design/BSP + external security review
B41: Blended ARPU (price × mix) | C41: =SUMPRODUCT('02_Property_Sizes'!P6:P10,'02_Property_Sizes'!M6:M10) -> 439.5 | D41: $/month | E41: Computed from tier prices × mix
B42: Blended COGS / property (live) | C42: =SUMPRODUCT('02_Property_Sizes'!P6:P10,'03_Unit_Economics'!M6:M10) -> 67.808214 | D42: $/month | E42: Computed from per-tier COGS × mix
B43: Blended gross profit / property | C43: =C41-C42 -> 371.69179 | D43: $/month | E43: Used for breakeven property count

Sheet 02_Property_Sizes
B2: Property archetypes — drivers, price and mix
B3: The five sizes we sell to. Engagement per room falls as properties grow; price per room falls with it.
B5: Tier | C5: Segment | D5: Rooms | E5: Occupancy | F5: Conversations / room / mo | G5: Messages / conversation | H5: WhatsApp share | I5: Escalation rate | J5: Staff min / escalation | K5: Support hours / mo | L5: Onboarding hours | M5: List price $/mo | N5: Setup fee $ | O5: WhatsApp $/message | P5: Share of new logos
B6: T1 | C6: Boutique / casita | D6: 15 | E6: 0.7 | F6: 3 | G6: 7 | H6: 0.6 | I6: 0.3 | J6: 6 | K6: 0.9 | L6: 2.5 | M6: 299 | N6: 500 | O6: 0.0085 | P6: 0.2
B7: T2 | C7: Boutique luxury | D7: 30 | E7: 0.72 | F7: 2.6 | G7: 7 | H7: 0.65 | I7: 0.28 | J7: 6 | K7: 1.1 | L7: 3 | M7: 349 | N7: 500 | O7: 0.0085 | P7: 0.42
B8: T3 | C8: Luxury city hotel | D8: 60 | E8: 0.75 | F8: 2.2 | G8: 8 | H8: 0.7 | I8: 0.25 | J8: 7 | K8: 1.4 | L8: 4 | M8: 449 | N8: 500 | O8: 0.0085 | P8: 0.23
B9: T4 | C9: Resort | D9: 120 | E9: 0.78 | F9: 1.9 | G9: 8 | H9: 0.72 | I9: 0.24 | J9: 7 | K9: 1.9 | L9: 5.5 | M9: 699 | N9: 750 | O9: 0.0085 | P9: 0.1
B10: T5 | C10: Large resort / flagship | D10: 250 | E10: 0.8 | F10: 1.7 | G10: 9 | H10: 0.75 | I10: 0.22 | J10: 8 | K10: 2.8 | L10: 7.5 | M10: 1199 | N10: 1000 | O10: 0.0085 | P10: 0.05
B11: Total | P11: =SUM(P6:P10) -> 1 | Q11: =IF(ABS(P11-1)<0.0001,"mix OK","FIX MIX") -> mix OK | R11: ← must equal 100%
B13: Derived per-property metrics (formulas)
B14: Feeds 03_Unit_Economics, 04_Messaging_Costs and the ramp model.
B16: Tier | C16: Conversations / mo | D16: Business messages / mo | E16: WhatsApp messages / mo | F16: Billable WhatsApp msgs / mo | G16: Effective price / room / mo | H16: Conv. / room (check)
B17: =B6 -> T1 | C17: =D6*F6 -> 45 | D17: =C17*G6 -> 315 | E17: =D17*H6 -> 189 | F17: =MAX(0,E17-'01_Assumptions'!C25) -> 0 | G17: =M6/D6 -> 19.933333 | H17: =F6 -> 3
B18: =B7 -> T2 | C18: =D7*F7 -> 78 | D18: =C18*G7 -> 546 | E18: =D18*H7 -> 354.9 | F18: =MAX(0,E18-'01_Assumptions'!C25) -> 0 | G18: =M7/D7 -> 11.633333 | H18: =F7 -> 2.6
B19: =B8 -> T3 | C19: =D8*F8 -> 132 | D19: =C19*G8 -> 1056 | E19: =D19*H8 -> 739.2 | F19: =MAX(0,E19-'01_Assumptions'!C25) -> 0 | G19: =M8/D8 -> 7.4833333 | H19: =F8 -> 2.2
B20: =B9 -> T4 | C20: =D9*F9 -> 228 | D20: =C20*G9 -> 1824 | E20: =D20*H9 -> 1313.28 | F20: =MAX(0,E20-'01_Assumptions'!C25) -> 313.28 | G20: =M9/D9 -> 5.825 | H20: =F9 -> 1.9
B21: =B10 -> T5 | C21: =D10*F10 -> 425 | D21: =C21*G10 -> 3825 | E21: =D21*H10 -> 2868.75 | F21: =MAX(0,E21-'01_Assumptions'!C25) -> 1868.75 | G21: =M10/D10 -> 4.796 | H21: =F10 -> 1.7

Sheet 03_Unit_Economics
B2: Unit economics per property — by size
B3: Fully loaded: messaging + AI + infra + support labour + card fees. Gross margin is conservative by design.
B5: Tier | C5: Segment | D5: Rooms | E5: Price $/mo | F5: Revenue $/yr | G5: Conversations / mo | H5: WhatsApp cost / mo | I5: LLM + aux / mo | J5: Infra alloc / mo | K5: Support labour / mo | L5: Card fees / mo | M5: Total COGS / mo | N5: Gross profit / mo | O5: Gross margin | P5: COGS $ /property | Q5: GP / room / mo | R5: Price / room / mo | S5: Support hrs / mo | T5: GP per support hour | U5: Onboarding cost | V5: Setup fee revenue | W5: Onboarding margin | X5: CAC | Y5: Payback (months) | Z5: LTV (churn-based) | AA5: LTV / CAC | AB5: Annual gross profit
B6: ='02_Property_Sizes'!B6 -> T1 | C6: ='02_Property_Sizes'!C6 -> Boutique / casita | D6: ='02_Property_Sizes'!D6 -> 15 | E6: ='02_Property_Sizes'!M6 -> 299 | F6: =E6*12 -> 3588 | G6: ='02_Property_Sizes'!C17 -> 45 | H6: ='02_Property_Sizes'!F17*'02_Property_Sizes'!O6*(1+'01_Assumptions'!C24) -> 0 | I6: =G6*'01_Assumptions'!C19/1000000*'01_Assumptions'!C17+G6*'01_Assumptions'!C20/1000000*'01_Assumptions'!C18+G6*'01_Assumptions'!C21 -> 0.18675 | J6: ='01_Assumptions'!C12/'01_Assumptions'!C13+'01_Assumptions'!C14 -> 11.9 | K6: ='02_Property_Sizes'!K6*'01_Assumptions'!C6 -> 28.8 | L6: =E6*'01_Assumptions'!C9 -> 8.671 | M6: =SUM(H6:L6) -> 49.55775 | N6: =E6-M6 -> 249.44225 | O6: =N6/E6 -> 0.83425502 | P6: =M6 -> 49.55775 | Q6: =N6/D6 -> 16.629483 | R6: =E6/D6 -> 19.933333 | S6: ='02_Property_Sizes'!K6 -> 0.9 | T6: =N6/S6 -> 277.15806 | U6: ='02_Property_Sizes'!L6*'01_Assumptions'!C7 -> 80 | V6: ='02_Property_Sizes'!N6 -> 500 | W6: =V6-U6 -> 420 | X6: ='01_Assumptions'!C33 -> 900 | Y6: =X6/(E6*O6) -> 3.6080496 | Z6: =N6/'01_Assumptions'!C31 -> 9977.69 | AA6: =Z6/X6 -> 11.086322 | AB6: =N6*12 -> 2993.307
B7: ='02_Property_Sizes'!B7 -> T2 | C7: ='02_Property_Sizes'!C7 -> Boutique luxury | D7: ='02_Property_Sizes'!D7 -> 30 | E7: ='02_Property_Sizes'!M7 -> 349 | F7: =E7*12 -> 4188 | G7: ='02_Property_Sizes'!C18 -> 78 | H7: ='02_Property_Sizes'!F18*'02_Property_Sizes'!O7*(1+'01_Assumptions'!C24) -> 0 | I7: =G7*'01_Assumptions'!C19/1000000*'01_Assumptions'!C17+G7*'01_Assumptions'!C20/1000000*'01_Assumptions'!C18+G7*'01_Assumptions'!C21 -> 0.3237 | J7: ='01_Assumptions'!C12/'01_Assumptions'!C13+'01_Assumptions'!C14 -> 11.9 | K7: ='02_Property_Sizes'!K7*'01_Assumptions'!C6 -> 35.2 | L7: =E7*'01_Assumptions'!C9 -> 10.121 | M7: =SUM(H7:L7) -> 57.5447 | N7: =E7-M7 -> 291.4553 | O7: =N7/E7 -> 0.83511547 | P7: =M7 -> 57.5447 | Q7: =N7/D7 -> 9.7151767 | R7: =E7/D7 -> 11.633333 | S7: ='02_Property_Sizes'!K7 -> 1.1 | T7: =N7/S7 -> 264.95936 | U7: ='02_Property_Sizes'!L7*'01_Assumptions'!C7 -> 96 | V7: ='02_Property_Sizes'!N7 -> 500 | W7: =V7-U7 -> 404 | X7: ='01_Assumptions'!C33 -> 900 | Y7: =X7/(E7*O7) -> 3.0879521 | Z7: =N7/'01_Assumptions'!C31 -> 11658.212 | AA7: =Z7/X7 -> 12.953569 | AB7: =N7*12 -> 3497.4636
B8: ='02_Property_Sizes'!B8 -> T3 | C8: ='02_Property_Sizes'!C8 -> Luxury city hotel | D8: ='02_Property_Sizes'!D8 -> 60 | E8: ='02_Property_Sizes'!M8 -> 449 | F8: =E8*12 -> 5388 | G8: ='02_Property_Sizes'!C19 -> 132 | H8: ='02_Property_Sizes'!F19*'02_Property_Sizes'!O8*(1+'01_Assumptions'!C24) -> 0 | I8: =G8*'01_Assumptions'!C19/1000000*'01_Assumptions'!C17+G8*'01_Assumptions'!C20/1000000*'01_Assumptions'!C18+G8*'01_Assumptions'!C21 -> 0.5478 | J8: ='01_Assumptions'!C12/'01_Assumptions'!C13+'01_Assumptions'!C14 -> 11.9 | K8: ='02_Property_Sizes'!K8*'01_Assumptions'!C6 -> 44.8 | L8: =E8*'01_Assumptions'!C9 -> 13.021 | M8: =SUM(H8:L8) -> 70.2688 | N8: =E8-M8 -> 378.7312 | O8: =N8/E8 -> 0.84349933 | P8: =M8 -> 70.2688 | Q8: =N8/D8 -> 6.3121867 | R8: =E8/D8 -> 7.4833333 | S8: ='02_Property_Sizes'!K8 -> 1.4 | T8: =N8/S8 -> 270.52229 | U8: ='02_Property_Sizes'!L8*'01_Assumptions'!C7 -> 128 | V8: ='02_Property_Sizes'!N8 -> 500 | W8: =V8-U8 -> 372 | X8: ='01_Assumptions'!C33 -> 900 | Y8: =X8/(E8*O8) -> 2.3763556 | Z8: =N8/'01_Assumptions'!C31 -> 15149.248 | AA8: =Z8/X8 -> 16.832498 | AB8: =N8*12 -> 4544.7744
B9: ='02_Property_Sizes'!B9 -> T4 | C9: ='02_Property_Sizes'!C9 -> Resort | D9: ='02_Property_Sizes'!D9 -> 120 | E9: ='02_Property_Sizes'!M9 -> 699 | F9: =E9*12 -> 8388 | G9: ='02_Property_Sizes'!C20 -> 228 | H9: ='02_Property_Sizes'!F20*'02_Property_Sizes'!O9*(1+'01_Assumptions'!C24) -> 3.195456 | I9: =G9*'01_Assumptions'!C19/1000000*'01_Assumptions'!C17+G9*'01_Assumptions'!C20/1000000*'01_Assumptions'!C18+G9*'01_Assumptions'!C21 -> 0.9462 | J9: ='01_Assumptions'!C12/'01_Assumptions'!C13+'01_Assumptions'!C14 -> 11.9 | K9: ='02_Property_Sizes'!K9*'01_Assumptions'!C6 -> 60.8 | L9: =E9*'01_Assumptions'!C9 -> 20.271 | M9: =SUM(H9:L9) -> 97.112656 | N9: =E9-M9 -> 601.88734 | O9: =N9/E9 -> 0.86106916 | P9: =M9 -> 97.112656 | Q9: =N9/D9 -> 5.0157279 | R9: =E9/D9 -> 5.825 | S9: ='02_Property_Sizes'!K9 -> 1.9 | T9: =N9/S9 -> 316.78281 | U9: ='02_Property_Sizes'!L9*'01_Assumptions'!C7 -> 176 | V9: ='02_Property_Sizes'!N9 -> 750 | W9: =V9-U9 -> 574 | X9: ='01_Assumptions'!C33 -> 900 | Y9: =X9/(E9*O9) -> 1.4952964 | Z9: =N9/'01_Assumptions'!C31 -> 24075.494 | AA9: =Z9/X9 -> 26.750549 | AB9: =N9*12 -> 7222.6481
B10: ='02_Property_Sizes'!B10 -> T5 | C10: ='02_Property_Sizes'!C10 -> Large resort / flagship | D10: ='02_Property_Sizes'!D10 -> 250 | E10: ='02_Property_Sizes'!M10 -> 1199 | F10: =E10*12 -> 14388 | G10: ='02_Property_Sizes'!C21 -> 425 | H10: ='02_Property_Sizes'!F21*'02_Property_Sizes'!O10*(1+'01_Assumptions'!C24) -> 19.06125 | I10: =G10*'01_Assumptions'!C19/1000000*'01_Assumptions'!C17+G10*'01_Assumptions'!C20/1000000*'01_Assumptions'!C18+G10*'01_Assumptions'!C21 -> 1.76375 | J10: ='01_Assumptions'!C12/'01_Assumptions'!C13+'01_Assumptions'!C14 -> 11.9 | K10: ='02_Property_Sizes'!K10*'01_Assumptions'!C6 -> 89.6 | L10: =E10*'01_Assumptions'!C9 -> 34.771 | M10: =SUM(H10:L10) -> 157.096 | N10: =E10-M10 -> 1041.904 | O10: =N10/E10 -> 0.86897748 | P10: =M10 -> 157.096 | Q10: =N10/D10 -> 4.167616 | R10: =E10/D10 -> 4.796 | S10: ='02_Property_Sizes'!K10 -> 2.8 | T10: =N10/S10 -> 372.10857 | U10: ='02_Property_Sizes'!L10*'01_Assumptions'!C7 -> 240 | V10: ='02_Property_Sizes'!N10 -> 1000 | W10: =V10-U10 -> 760 | X10: ='01_Assumptions'!C33 -> 900 | Y10: =X10/(E10*O10) -> 0.86380319 | Z10: =N10/'01_Assumptions'!C31 -> 41676.16 | AA10: =Z10/X10 -> 46.306844 | AB10: =N10*12 -> 12502.848
B12: Blended | C12: Portfolio mix | D12: =SUMPRODUCT('02_Property_Sizes'!$P$6:$P$10,'02_Property_Sizes'!$D$6:$D$10) -> 53.9 | E12: ='01_Assumptions'!C41 -> 439.5 | F12: =E12*12 -> 5274 | G12: =SUMPRODUCT('02_Property_Sizes'!$P$6:$P$10,'02_Property_Sizes'!$C$17:$C$21) -> 116.17 | H12: =SUMPRODUCT('02_Property_Sizes'!$P$6:$P$10,H6:H10) -> 1.2726081 | I12: =SUMPRODUCT('02_Property_Sizes'!$P$6:$P$10,I6:I10) -> 0.4821055 | J12: =SUMPRODUCT('02_Property_Sizes'!$P$6:$P$10,J6:J10) -> 11.9 | K12: =SUMPRODUCT('02_Property_Sizes'!$P$6:$P$10,K6:K10) -> 41.408 | L12: =SUMPRODUCT('02_Property_Sizes'!$P$6:$P$10,L6:L10) -> 12.7455 | M12: =SUM(H12:L12) -> 67.808214 | N12: =E12-M12 -> 371.69179 | O12: =N12/E12 -> 0.8457151 | P12: =M12 -> 67.808214 | Q12: =N12/D12 -> 6.8959515 | R12: =E12/D12 -> 8.1539889 | S12: =SUMPRODUCT('02_Property_Sizes'!$P$6:$P$10,S6:S10) -> 1.294 | T12: =N12/S12 -> 287.24249 | U12: =SUMPRODUCT('02_Property_Sizes'!$P$6:$P$10,U6:U10) -> 115.36 | V12: =SUMPRODUCT('02_Property_Sizes'!$P$6:$P$10,V6:V10) -> 550 | W12: =V12-U12 -> 434.64 | X12: ='01_Assumptions'!C33 -> 900 | Y12: =X12/(E12*O12) -> 2.421361 | Z12: =N12/'01_Assumptions'!C31 -> 14867.671 | AA12: =Z12/X12 -> 16.519635 | AB12: =N12*12 -> 4460.3014
B14: Read-across
B15: • Gross margin climbs with size: fixed support and infra are spread over more rooms, and the price-per-room taper is gentler than the fall in cost per room.
B16: • Messaging is not the margin threat at MVP volumes. Even at ~1,500 WhatsApp messages/month the fee is single-digit dollars in Mexico and the US; it only bites above ~2,500 messages/month in high-rate markets (Germany, UK, Spain).
B17: • Onboarding labour is the real cost centre. At T5 the setup fee barely covers the knowledge work — do not waive it above T3.
B18: • Payback under four months at every size means growth is self-funding from month one. The binding constraints are founder selling time and support hours, not capital.
B19: • LTV uses a churn-based multiple and includes support labour in COGS, so it sits closer to reality than a revenue-multiple LTV.

Sheet 04_Messaging_Costs
B2: WhatsApp cost by market (Meta pricing, effective 1 Oct 2026)
B3: Service messages — free-form replies inside the 24h window — became billable on 1 Oct 2026, after 1,000 free per number per month.
B5: Market | C5: Marketing $/msg | D5: Utility $/msg | E5: Service $/msg | F5: Note
B6: Mexico | C6: 0.0397 | D6: 0.0085 | E6: 0.0085 | F6: Primary market; low service rate
B7: United States | C7: 0.025 | D7: 0.0034 | E7: 0.0034 | F7: Inbound guests; very low
B8: Spain | C8: 0.0707 | D8: 0.02 | E8: 0.02 | F8: 2.4x Mexico
B9: United Kingdom | C9: 0.0635 | D9: 0.022 | E9: 0.022 | F9: 2.6x Mexico
B10: Germany | C10: 0.1365 | D10: 0.055 | E10: 0.055 | F10: 6.5x Mexico — worst case
B11: Brazil | C11: 0.0625 | D11: 0.0068 | E11: 0.0068 | F11: Low service rate
B12: India | C12: 0.0118 | D12: 0.0014 | E12: 0.0014 | F12: Lowest
B15: Service-message cost per property per month (after 1,000 free), by size × market
B16: Includes the 20% BSP markup from 01_Assumptions.
B17: Size | C17: Mexico | D17: United States | E17: Spain | F17: United Kingdom | G17: Germany | H17: Brazil | I17: India
B18: ='02_Property_Sizes'!B17 -> T1 | C18: =MAX(0,'02_Property_Sizes'!E17-'01_Assumptions'!C25)*C6*(1+'01_Assumptions'!C24) -> 0 | D18: =MAX(0,'02_Property_Sizes'!E17-'01_Assumptions'!C25)*D7*(1+'01_Assumptions'!C24) -> 0 | E18: =MAX(0,'02_Property_Sizes'!E17-'01_Assumptions'!C25)*E8*(1+'01_Assumptions'!C24) -> 0 | F18: =MAX(0,'02_Property_Sizes'!E17-'01_Assumptions'!C25)*F9*(1+'01_Assumptions'!C24) -> #VALUE! | G18: =MAX(0,'02_Property_Sizes'!E17-'01_Assumptions'!C25)*G10*(1+'01_Assumptions'!C24) -> 0 | H18: =MAX(0,'02_Property_Sizes'!E17-'01_Assumptions'!C25)*H11*(1+'01_Assumptions'!C24) -> 0 | I18: =MAX(0,'02_Property_Sizes'!E17-'01_Assumptions'!C25)*I12*(1+'01_Assumptions'!C24) -> 0
B19: ='02_Property_Sizes'!B18 -> T2 | C19: =MAX(0,'02_Property_Sizes'!E18-'01_Assumptions'!C25)*C6*(1+'01_Assumptions'!C24) -> 0 | D19: =MAX(0,'02_Property_Sizes'!E18-'01_Assumptions'!C25)*D7*(1+'01_Assumptions'!C24) -> 0 | E19: =MAX(0,'02_Property_Sizes'!E18-'01_Assumptions'!C25)*E8*(1+'01_Assumptions'!C24) -> 0 | F19: =MAX(0,'02_Property_Sizes'!E18-'01_Assumptions'!C25)*F9*(1+'01_Assumptions'!C24) -> #VALUE! | G19: =MAX(0,'02_Property_Sizes'!E18-'01_Assumptions'!C25)*G10*(1+'01_Assumptions'!C24) -> 0 | H19: =MAX(0,'02_Property_Sizes'!E18-'01_Assumptions'!C25)*H11*(1+'01_Assumptions'!C24) -> 0 | I19: =MAX(0,'02_Property_Sizes'!E18-'01_Assumptions'!C25)*I12*(1+'01_Assumptions'!C24) -> 0
B20: ='02_Property_Sizes'!B19 -> T3 | C20: =MAX(0,'02_Property_Sizes'!E19-'01_Assumptions'!C25)*C6*(1+'01_Assumptions'!C24) -> 0 | D20: =MAX(0,'02_Property_Sizes'!E19-'01_Assumptions'!C25)*D7*(1+'01_Assumptions'!C24) -> 0 | E20: =MAX(0,'02_Property_Sizes'!E19-'01_Assumptions'!C25)*E8*(1+'01_Assumptions'!C24) -> 0 | F20: =MAX(0,'02_Property_Sizes'!E19-'01_Assumptions'!C25)*F9*(1+'01_Assumptions'!C24) -> #VALUE! | G20: =MAX(0,'02_Property_Sizes'!E19-'01_Assumptions'!C25)*G10*(1+'01_Assumptions'!C24) -> 0 | H20: =MAX(0,'02_Property_Sizes'!E19-'01_Assumptions'!C25)*H11*(1+'01_Assumptions'!C24) -> 0 | I20: =MAX(0,'02_Property_Sizes'!E19-'01_Assumptions'!C25)*I12*(1+'01_Assumptions'!C24) -> 0
B21: ='02_Property_Sizes'!B20 -> T4 | C21: =MAX(0,'02_Property_Sizes'!E20-'01_Assumptions'!C25)*C6*(1+'01_Assumptions'!C24) -> 14.924659 | D21: =MAX(0,'02_Property_Sizes'!E20-'01_Assumptions'!C25)*D7*(1+'01_Assumptions'!C24) -> 1.2781824 | E21: =MAX(0,'02_Property_Sizes'!E20-'01_Assumptions'!C25)*E8*(1+'01_Assumptions'!C24) -> 7.51872 | F21: =MAX(0,'02_Property_Sizes'!E20-'01_Assumptions'!C25)*F9*(1+'01_Assumptions'!C24) -> #VALUE! | G21: =MAX(0,'02_Property_Sizes'!E20-'01_Assumptions'!C25)*G10*(1+'01_Assumptions'!C24) -> 0 | H21: =MAX(0,'02_Property_Sizes'!E20-'01_Assumptions'!C25)*H11*(1+'01_Assumptions'!C24) -> 0 | I21: =MAX(0,'02_Property_Sizes'!E20-'01_Assumptions'!C25)*I12*(1+'01_Assumptions'!C24) -> 0
B22: ='02_Property_Sizes'!B21 -> T5 | C22: =MAX(0,'02_Property_Sizes'!E21-'01_Assumptions'!C25)*C6*(1+'01_Assumptions'!C24) -> 89.02725 | D22: =MAX(0,'02_Property_Sizes'!E21-'01_Assumptions'!C25)*D7*(1+'01_Assumptions'!C24) -> 7.6245 | E22: =MAX(0,'02_Property_Sizes'!E21-'01_Assumptions'!C25)*E8*(1+'01_Assumptions'!C24) -> 44.85 | F22: =MAX(0,'02_Property_Sizes'!E21-'01_Assumptions'!C25)*F9*(1+'01_Assumptions'!C24) -> #VALUE! | G22: =MAX(0,'02_Property_Sizes'!E21-'01_Assumptions'!C25)*G10*(1+'01_Assumptions'!C24) -> 0 | H22: =MAX(0,'02_Property_Sizes'!E21-'01_Assumptions'!C25)*H11*(1+'01_Assumptions'!C24) -> 0 | I22: =MAX(0,'02_Property_Sizes'!E21-'01_Assumptions'!C25)*I12*(1+'01_Assumptions'!C24) -> 0
B24: Cost per 100 conversations, by market
B25: Assumes 5 hotel messages per conversation and ignores the monthly 1,000 free allowance (conservative at scale).
B26: Metric | C26: Mexico | D26: Germany | E26: United States
B27: Billable messages per 100 conversations | C27: =100*'01_Assumptions'!C26 -> 500 | D27: =100*'01_Assumptions'!C26 -> 500 | E27: =100*'01_Assumptions'!C26 -> 500
B28: Cost per 100 conversations (incl. markup) | C28: =C27*E6*(1+'01_Assumptions'!C24) -> 5.1 | D28: =C27*E10*(1+'01_Assumptions'!C24) -> 33 | E28: =C27*E7*(1+'01_Assumptions'!C24) -> 2.04
B30: How to use this
B31: • Set the blended $/message on 02_Property_Sizes to the hotel's market. Mexico and US properties will never notice this line; a German or Spanish property will.
B32: • Utility templates sent OUTSIDE the 24h window are charged at the utility rate — budget those per campaign, not per conversation.
B33: • Messages inside a free entry point window (Click-to-WhatsApp ads) are not charged. Where a property runs CTWA, route acquisition traffic there.
B34: • Design consequence: keep replies efficient. Message count, not token count, is the unit of WhatsApp cost.

Sheet 05_Ramp
B2: 24-month ramp — three scenarios
B3: Pilots are the only hard input. New paid properties convert with a one-month lag; churn hits the opening base.
B5: Scenario parameters
B6: Scenario | C6: Pilot→paid | D6: Monthly churn | E6: ARPU $/mo | F6: COGS $/property | G6: Opex base | H6: Opex step | I6: Threshold 1 | J6: Threshold 2 | K6: Setup realization
B7: Conservative | C7: 0.55 | D7: 0.03 | E7: ='01_Assumptions'!C41 -> 439.5 | F7: ='01_Assumptions'!C42 -> 67.808214 | G7: ='01_Assumptions'!C36 -> 7200 | H7: ='01_Assumptions'!C37 -> 3600 | I7: ='01_Assumptions'!C38 -> 25 | J7: ='01_Assumptions'!C39 -> 55 | K7: =1-'01_Assumptions'!C30 -> 0.5
B8: Base | C8: 0.6 | D8: 0.025 | E8: ='01_Assumptions'!C41 -> 439.5 | F8: ='01_Assumptions'!C42 -> 67.808214 | G8: ='01_Assumptions'!C36 -> 7200 | H8: ='01_Assumptions'!C37 -> 3600 | I8: ='01_Assumptions'!C38 -> 25 | J8: ='01_Assumptions'!C39 -> 55 | K8: =1-'01_Assumptions'!C30 -> 0.5
B9: Aggressive | C9: 0.7 | D9: 0.018 | E9: ='01_Assumptions'!C41 -> 439.5 | F9: ='01_Assumptions'!C42 -> 67.808214 | G9: ='01_Assumptions'!C36 -> 7200 | H9: ='01_Assumptions'!C37 -> 3600 | I9: ='01_Assumptions'!C38 -> 25 | J9: ='01_Assumptions'!C39 -> 55 | K9: =1-'01_Assumptions'!C30 -> 0.5
B10: CONSERVATIVE — monthly model
B11: Month | C11: New pilots | D11: Active properties BOP | E11: New paid | F11: Churned | G11: Active properties EOP | H11: Subscription MRR | I11: Setup cash | J11: Total revenue | K11: COGS | L11: Fixed opex | M11: Net cash flow | N11: Cumulative cash | O11: Profitable? | P11: Cash-positive? | Q11: Note
B12: 1 | C12: 1 | D12: 0 | E12: 0 | F12: 0 | G12: =D12+E12-F12 -> 0 | H12: =G12*$E$7 -> 0 | I12: =E12*'01_Assumptions'!C29*$K$7 -> 0 | J12: =H12+I12 -> 0 | K12: =G12*$F$7 -> 0 | L12: =$G$7+IF(G12>=$I$7,$H$7,0)+IF(G12>=$J$7,$H$7,0) -> 7200 | M12: =J12-K12-L12 -> -7200 | N12: =-'01_Assumptions'!C40+M12 -> -24200 | O12: =IF(M12>0,1,0) -> 0 | P12: =IF(N12>=0,1,0) -> 0
B13: 2 | C13: 1 | D13: =G12 -> 0 | E13: =ROUND(C12*$C$7,0) -> 1 | F13: =ROUND(D13*$D$7,0) -> 0 | G13: =D13+E13-F13 -> 1 | H13: =G13*$E$7 -> 439.5 | I13: =E13*'01_Assumptions'!C29*$K$7 -> 250 | J13: =H13+I13 -> 689.5 | K13: =G13*$F$7 -> 67.808214 | L13: =$G$7+IF(G13>=$I$7,$H$7,0)+IF(G13>=$J$7,$H$7,0) -> 7200 | M13: =J13-K13-L13 -> -6578.3082 | N13: =N12+M13 -> -30778.308 | O13: =IF(M13>0,1,0) -> 0 | P13: =IF(N13>=0,1,0) -> 0
B14: 3 | C14: 1 | D14: =G13 -> 1 | E14: =ROUND(C13*$C$7,0) -> 1 | F14: =ROUND(D14*$D$7,0) -> 0 | G14: =D14+E14-F14 -> 2 | H14: =G14*$E$7 -> 879 | I14: =E14*'01_Assumptions'!C29*$K$7 -> 250 | J14: =H14+I14 -> 1129 | K14: =G14*$F$7 -> 135.61643 | L14: =$G$7+IF(G14>=$I$7,$H$7,0)+IF(G14>=$J$7,$H$7,0) -> 7200 | M14: =J14-K14-L14 -> -6206.6164 | N14: =N13+M14 -> -36984.925 | O14: =IF(M14>0,1,0) -> 0 | P14: =IF(N14>=0,1,0) -> 0
B15: 4 | C15: 1 | D15: =G14 -> 2 | E15: =ROUND(C14*$C$7,0) -> 1 | F15: =ROUND(D15*$D$7,0) -> 0 | G15: =D15+E15-F15 -> 3 | H15: =G15*$E$7 -> 1318.5 | I15: =E15*'01_Assumptions'!C29*$K$7 -> 250 | J15: =H15+I15 -> 1568.5 | K15: =G15*$F$7 -> 203.42464 | L15: =$G$7+IF(G15>=$I$7,$H$7,0)+IF(G15>=$J$7,$H$7,0) -> 7200 | M15: =J15-K15-L15 -> -5834.9246 | N15: =N14+M15 -> -42819.849 | O15: =IF(M15>0,1,0) -> 0 | P15: =IF(N15>=0,1,0) -> 0
B16: 5 | C16: 2 | D16: =G15 -> 3 | E16: =ROUND(C15*$C$7,0) -> 1 | F16: =ROUND(D16*$D$7,0) -> 0 | G16: =D16+E16-F16 -> 4 | H16: =G16*$E$7 -> 1758 | I16: =E16*'01_Assumptions'!C29*$K$7 -> 250 | J16: =H16+I16 -> 2008 | K16: =G16*$F$7 -> 271.23285 | L16: =$G$7+IF(G16>=$I$7,$H$7,0)+IF(G16>=$J$7,$H$7,0) -> 7200 | M16: =J16-K16-L16 -> -5463.2329 | N16: =N15+M16 -> -48283.082 | O16: =IF(M16>0,1,0) -> 0 | P16: =IF(N16>=0,1,0) -> 0
B17: 6 | C17: 2 | D17: =G16 -> 4 | E17: =ROUND(C16*$C$7,0) -> 1 | F17: =ROUND(D17*$D$7,0) -> 0 | G17: =D17+E17-F17 -> 5 | H17: =G17*$E$7 -> 2197.5 | I17: =E17*'01_Assumptions'!C29*$K$7 -> 250 | J17: =H17+I17 -> 2447.5 | K17: =G17*$F$7 -> 339.04107 | L17: =$G$7+IF(G17>=$I$7,$H$7,0)+IF(G17>=$J$7,$H$7,0) -> 7200 | M17: =J17-K17-L17 -> -5091.5411 | N17: =N16+M17 -> -53374.623 | O17: =IF(M17>0,1,0) -> 0 | P17: =IF(N17>=0,1,0) -> 0
B18: 7 | C18: 2 | D18: =G17 -> 5 | E18: =ROUND(C17*$C$7,0) -> 1 | F18: =ROUND(D18*$D$7,0) -> 0 | G18: =D18+E18-F18 -> 6 | H18: =G18*$E$7 -> 2637 | I18: =E18*'01_Assumptions'!C29*$K$7 -> 250 | J18: =H18+I18 -> 2887 | K18: =G18*$F$7 -> 406.84928 | L18: =$G$7+IF(G18>=$I$7,$H$7,0)+IF(G18>=$J$7,$H$7,0) -> 7200 | M18: =J18-K18-L18 -> -4719.8493 | N18: =N17+M18 -> -58094.472 | O18: =IF(M18>0,1,0) -> 0 | P18: =IF(N18>=0,1,0) -> 0
B19: 8 | C19: 2 | D19: =G18 -> 6 | E19: =ROUND(C18*$C$7,0) -> 1 | F19: =ROUND(D19*$D$7,0) -> 0 | G19: =D19+E19-F19 -> 7 | H19: =G19*$E$7 -> 3076.5 | I19: =E19*'01_Assumptions'!C29*$K$7 -> 250 | J19: =H19+I19 -> 3326.5 | K19: =G19*$F$7 -> 474.6575 | L19: =$G$7+IF(G19>=$I$7,$H$7,0)+IF(G19>=$J$7,$H$7,0) -> 7200 | M19: =J19-K19-L19 -> -4348.1575 | N19: =N18+M19 -> -62442.63 | O19: =IF(M19>0,1,0) -> 0 | P19: =IF(N19>=0,1,0) -> 0
B20: 9 | C20: 2 | D20: =G19 -> 7 | E20: =ROUND(C19*$C$7,0) -> 1 | F20: =ROUND(D20*$D$7,0) -> 0 | G20: =D20+E20-F20 -> 8 | H20: =G20*$E$7 -> 3516 | I20: =E20*'01_Assumptions'!C29*$K$7 -> 250 | J20: =H20+I20 -> 3766 | K20: =G20*$F$7 -> 542.46571 | L20: =$G$7+IF(G20>=$I$7,$H$7,0)+IF(G20>=$J$7,$H$7,0) -> 7200 | M20: =J20-K20-L20 -> -3976.4657 | N20: =N19+M20 -> -66419.096 | O20: =IF(M20>0,1,0) -> 0 | P20: =IF(N20>=0,1,0) -> 0
B21: 10 | C21: 2 | D21: =G20 -> 8 | E21: =ROUND(C20*$C$7,0) -> 1 | F21: =ROUND(D21*$D$7,0) -> 0 | G21: =D21+E21-F21 -> 9 | H21: =G21*$E$7 -> 3955.5 | I21: =E21*'01_Assumptions'!C29*$K$7 -> 250 | J21: =H21+I21 -> 4205.5 | K21: =G21*$F$7 -> 610.27392 | L21: =$G$7+IF(G21>=$I$7,$H$7,0)+IF(G21>=$J$7,$H$7,0) -> 7200 | M21: =J21-K21-L21 -> -3604.7739 | N21: =N20+M21 -> -70023.87 | O21: =IF(M21>0,1,0) -> 0 | P21: =IF(N21>=0,1,0) -> 0
B22: 11 | C22: 2 | D22: =G21 -> 9 | E22: =ROUND(C21*$C$7,0) -> 1 | F22: =ROUND(D22*$D$7,0) -> 0 | G22: =D22+E22-F22 -> 10 | H22: =G22*$E$7 -> 4395 | I22: =E22*'01_Assumptions'!C29*$K$7 -> 250 | J22: =H22+I22 -> 4645 | K22: =G22*$F$7 -> 678.08214 | L22: =$G$7+IF(G22>=$I$7,$H$7,0)+IF(G22>=$J$7,$H$7,0) -> 7200 | M22: =J22-K22-L22 -> -3233.0821 | N22: =N21+M22 -> -73256.952 | O22: =IF(M22>0,1,0) -> 0 | P22: =IF(N22>=0,1,0) -> 0
B23: 12 | C23: 2 | D23: =G22 -> 10 | E23: =ROUND(C22*$C$7,0) -> 1 | F23: =ROUND(D23*$D$7,0) -> 0 | G23: =D23+E23-F23 -> 11 | H23: =G23*$E$7 -> 4834.5 | I23: =E23*'01_Assumptions'!C29*$K$7 -> 250 | J23: =H23+I23 -> 5084.5 | K23: =G23*$F$7 -> 745.89035 | L23: =$G$7+IF(G23>=$I$7,$H$7,0)+IF(G23>=$J$7,$H$7,0) -> 7200 | M23: =J23-K23-L23 -> -2861.3903 | N23: =N22+M23 -> -76118.342 | O23: =IF(M23>0,1,0) -> 0 | P23: =IF(N23>=0,1,0) -> 0
B24: 13 | C24: 3 | D24: =G23 -> 11 | E24: =ROUND(C23*$C$7,0) -> 1 | F24: =ROUND(D24*$D$7,0) -> 0 | G24: =D24+E24-F24 -> 12 | H24: =G24*$E$7 -> 5274 | I24: =E24*'01_Assumptions'!C29*$K$7 -> 250 | J24: =H24+I24 -> 5524 | K24: =G24*$F$7 -> 813.69856 | L24: =$G$7+IF(G24>=$I$7,$H$7,0)+IF(G24>=$J$7,$H$7,0) -> 7200 | M24: =J24-K24-L24 -> -2489.6986 | N24: =N23+M24 -> -78608.041 | O24: =IF(M24>0,1,0) -> 0 | P24: =IF(N24>=0,1,0) -> 0
B25: 14 | C25: 3 | D25: =G24 -> 12 | E25: =ROUND(C24*$C$7,0) -> 2 | F25: =ROUND(D25*$D$7,0) -> 0 | G25: =D25+E25-F25 -> 14 | H25: =G25*$E$7 -> 6153 | I25: =E25*'01_Assumptions'!C29*$K$7 -> 500 | J25: =H25+I25 -> 6653 | K25: =G25*$F$7 -> 949.31499 | L25: =$G$7+IF(G25>=$I$7,$H$7,0)+IF(G25>=$J$7,$H$7,0) -> 7200 | M25: =J25-K25-L25 -> -1496.315 | N25: =N24+M25 -> -80104.356 | O25: =IF(M25>0,1,0) -> 0 | P25: =IF(N25>=0,1,0) -> 0
B26: 15 | C26: 3 | D26: =G25 -> 14 | E26: =ROUND(C25*$C$7,0) -> 2 | F26: =ROUND(D26*$D$7,0) -> 0 | G26: =D26+E26-F26 -> 16 | H26: =G26*$E$7 -> 7032 | I26: =E26*'01_Assumptions'!C29*$K$7 -> 500 | J26: =H26+I26 -> 7532 | K26: =G26*$F$7 -> 1084.9314 | L26: =$G$7+IF(G26>=$I$7,$H$7,0)+IF(G26>=$J$7,$H$7,0) -> 7200 | M26: =J26-K26-L26 -> -752.93142 | N26: =N25+M26 -> -80857.287 | O26: =IF(M26>0,1,0) -> 0 | P26: =IF(N26>=0,1,0) -> 0
B27: 16 | C27: 3 | D27: =G26 -> 16 | E27: =ROUND(C26*$C$7,0) -> 2 | F27: =ROUND(D27*$D$7,0) -> 0 | G27: =D27+E27-F27 -> 18 | H27: =G27*$E$7 -> 7911 | I27: =E27*'01_Assumptions'!C29*$K$7 -> 500 | J27: =H27+I27 -> 8411 | K27: =G27*$F$7 -> 1220.5478 | L27: =$G$7+IF(G27>=$I$7,$H$7,0)+IF(G27>=$J$7,$H$7,0) -> 7200 | M27: =J27-K27-L27 -> -9.5478448 | N27: =N26+M27 -> -80866.835 | O27: =IF(M27>0,1,0) -> 0 | P27: =IF(N27>=0,1,0) -> 0
B28: 17 | C28: 3 | D28: =G27 -> 18 | E28: =ROUND(C27*$C$7,0) -> 2 | F28: =ROUND(D28*$D$7,0) -> 1 | G28: =D28+E28-F28 -> 19 | H28: =G28*$E$7 -> 8350.5 | I28: =E28*'01_Assumptions'!C29*$K$7 -> 500 | J28: =H28+I28 -> 8850.5 | K28: =G28*$F$7 -> 1288.3561 | L28: =$G$7+IF(G28>=$I$7,$H$7,0)+IF(G28>=$J$7,$H$7,0) -> 7200 | M28: =J28-K28-L28 -> 362.14394 | N28: =N27+M28 -> -80504.691 | O28: =IF(M28>0,1,0) -> 1 | P28: =IF(N28>=0,1,0) -> 0
B29: 18 | C29: 3 | D29: =G28 -> 19 | E29: =ROUND(C28*$C$7,0) -> 2 | F29: =ROUND(D29*$D$7,0) -> 1 | G29: =D29+E29-F29 -> 20 | H29: =G29*$E$7 -> 8790 | I29: =E29*'01_Assumptions'!C29*$K$7 -> 500 | J29: =H29+I29 -> 9290 | K29: =G29*$F$7 -> 1356.1643 | L29: =$G$7+IF(G29>=$I$7,$H$7,0)+IF(G29>=$J$7,$H$7,0) -> 7200 | M29: =J29-K29-L29 -> 733.83573 | N29: =N28+M29 -> -79770.855 | O29: =IF(M29>0,1,0) -> 1 | P29: =IF(N29>=0,1,0) -> 0
B30: 19 | C30: 3 | D30: =G29 -> 20 | E30: =ROUND(C29*$C$7,0) -> 2 | F30: =ROUND(D30*$D$7,0) -> 1 | G30: =D30+E30-F30 -> 21 | H30: =G30*$E$7 -> 9229.5 | I30: =E30*'01_Assumptions'!C29*$K$7 -> 500 | J30: =H30+I30 -> 9729.5 | K30: =G30*$F$7 -> 1423.9725 | L30: =$G$7+IF(G30>=$I$7,$H$7,0)+IF(G30>=$J$7,$H$7,0) -> 7200 | M30: =J30-K30-L30 -> 1105.5275 | N30: =N29+M30 -> -78665.328 | O30: =IF(M30>0,1,0) -> 1 | P30: =IF(N30>=0,1,0) -> 0
B31: 20 | C31: 3 | D31: =G30 -> 21 | E31: =ROUND(C30*$C$7,0) -> 2 | F31: =ROUND(D31*$D$7,0) -> 1 | G31: =D31+E31-F31 -> 22 | H31: =G31*$E$7 -> 9669 | I31: =E31*'01_Assumptions'!C29*$K$7 -> 500 | J31: =H31+I31 -> 10169 | K31: =G31*$F$7 -> 1491.7807 | L31: =$G$7+IF(G31>=$I$7,$H$7,0)+IF(G31>=$J$7,$H$7,0) -> 7200 | M31: =J31-K31-L31 -> 1477.2193 | N31: =N30+M31 -> -77188.108 | O31: =IF(M31>0,1,0) -> 1 | P31: =IF(N31>=0,1,0) -> 0
B32: 21 | C32: 3 | D32: =G31 -> 22 | E32: =ROUND(C31*$C$7,0) -> 2 | F32: =ROUND(D32*$D$7,0) -> 1 | G32: =D32+E32-F32 -> 23 | H32: =G32*$E$7 -> 10108.5 | I32: =E32*'01_Assumptions'!C29*$K$7 -> 500 | J32: =H32+I32 -> 10608.5 | K32: =G32*$F$7 -> 1559.5889 | L32: =$G$7+IF(G32>=$I$7,$H$7,0)+IF(G32>=$J$7,$H$7,0) -> 7200 | M32: =J32-K32-L32 -> 1848.9111 | N32: =N31+M32 -> -75339.197 | O32: =IF(M32>0,1,0) -> 1 | P32: =IF(N32>=0,1,0) -> 0
B33: 22 | C33: 3 | D33: =G32 -> 23 | E33: =ROUND(C32*$C$7,0) -> 2 | F33: =ROUND(D33*$D$7,0) -> 1 | G33: =D33+E33-F33 -> 24 | H33: =G33*$E$7 -> 10548 | I33: =E33*'01_Assumptions'!C29*$K$7 -> 500 | J33: =H33+I33 -> 11048 | K33: =G33*$F$7 -> 1627.3971 | L33: =$G$7+IF(G33>=$I$7,$H$7,0)+IF(G33>=$J$7,$H$7,0) -> 7200 | M33: =J33-K33-L33 -> 2220.6029 | N33: =N32+M33 -> -73118.594 | O33: =IF(M33>0,1,0) -> 1 | P33: =IF(N33>=0,1,0) -> 0
B34: 23 | C34: 3 | D34: =G33 -> 24 | E34: =ROUND(C33*$C$7,0) -> 2 | F34: =ROUND(D34*$D$7,0) -> 1 | G34: =D34+E34-F34 -> 25 | H34: =G34*$E$7 -> 10987.5 | I34: =E34*'01_Assumptions'!C29*$K$7 -> 500 | J34: =H34+I34 -> 11487.5 | K34: =G34*$F$7 -> 1695.2053 | L34: =$G$7+IF(G34>=$I$7,$H$7,0)+IF(G34>=$J$7,$H$7,0) -> 10800 | M34: =J34-K34-L34 -> -1007.7053 | N34: =N33+M34 -> -74126.3 | O34: =IF(M34>0,1,0) -> 0 | P34: =IF(N34>=0,1,0) -> 0
B35: 24 | C35: 3 | D35: =G34 -> 25 | E35: =ROUND(C34*$C$7,0) -> 2 | F35: =ROUND(D35*$D$7,0) -> 1 | G35: =D35+E35-F35 -> 26 | H35: =G35*$E$7 -> 11427 | I35: =E35*'01_Assumptions'!C29*$K$7 -> 500 | J35: =H35+I35 -> 11927 | K35: =G35*$F$7 -> 1763.0136 | L35: =$G$7+IF(G35>=$I$7,$H$7,0)+IF(G35>=$J$7,$H$7,0) -> 10800 | M35: =J35-K35-L35 -> -636.01355 | N35: =N34+M35 -> -74762.313 | O35: =IF(M35>0,1,0) -> 0 | P35: =IF(N35>=0,1,0) -> 0
B37: Summary | D37: Value
B38: Active properties, month 12 | D38: =G23 -> 11
B39: Active properties, month 24 | D39: =G35 -> 26
B40: MRR, month 12 | D40: =H23 -> 4834.5
B41: MRR, month 24 | D41: =H35 -> 11427
B42: ARR, month 24 | D42: =H35*12 -> 137124
B43: Total revenue, 24 months | D43: =SUM(J12:J35) -> 142987
...

Sheet 06_Scenarios
B2: Scenario comparison
B3: Everything here is pulled live from 05_Ramp.
B5: Metric | C5: Conservative | D5: Base | E5: Aggressive
B6: Active properties — month 12 | C6: ='05_Ramp'!D38 -> 11 | D6: ='05_Ramp'!D83 -> 18 | E6: ='05_Ramp'!D128 -> 31
B7: Active properties — month 24 | C7: ='05_Ramp'!D39 -> 26 | D7: ='05_Ramp'!D84 -> 31 | E7: ='05_Ramp'!D129 -> 77
B8: MRR — month 12 | C8: ='05_Ramp'!D40 -> 4834.5 | D8: ='05_Ramp'!D85 -> 7911 | E8: ='05_Ramp'!D130 -> 13624.5
B9: MRR — month 24 | C9: ='05_Ramp'!D41 -> 11427 | D9: ='05_Ramp'!D86 -> 13624.5 | E9: ='05_Ramp'!D131 -> 33841.5
B10: ARR — month 24 | C10: ='05_Ramp'!D42 -> 137124 | D10: ='05_Ramp'!D87 -> 163494 | E10: ='05_Ramp'!D132 -> 406098
B11: 24-month revenue | C11: ='05_Ramp'!D43 -> 142987 | D11: ='05_Ramp'!D88 -> 186300 | E11: ='05_Ramp'!D133 -> 376487
B12: 24-month COGS | C12: ='05_Ramp'!D44 -> 20749.313 | D12: ='05_Ramp'!D89 -> 27123.285 | E12: ='05_Ramp'!D134 -> 54653.42
B13: 24-month opex | C13: ='05_Ramp'!D45 -> 180000 | D13: ='05_Ramp'!D90 -> 198000 | E13: ='05_Ramp'!D135 -> 244800
B14: 24-month gross profit | C14: ='05_Ramp'!D46 -> 122237.69 | D14: ='05_Ramp'!D91 -> 159176.71 | E14: ='05_Ramp'!D136 -> 321833.58
B15: 24-month net cash | C15: ='05_Ramp'!D47 -> -57762.313 | D15: ='05_Ramp'!D92 -> -38823.285 | E15: ='05_Ramp'!D137 -> 77033.58
B16: Peak funding need | C16: ='05_Ramp'!D48 -> -80866.835 | D16: ='05_Ramp'!D93 -> -63960.972 | E16: ='05_Ramp'!D138 -> -54123.87
B17: First profitable month | C17: ='05_Ramp'!D49 -> 17 | D17: ='05_Ramp'!D94 -> 13 | E17: ='05_Ramp'!D139 -> 9
B18: Cash recovered month | C18: ='05_Ramp'!D50 -> beyond 24 | D18: ='05_Ramp'!D95 -> beyond 24 | E18: ='05_Ramp'!D140 -> 20
B20: Reading the model
B21: • Base case turns cash-flow-positive in month 13 and holds a positive MRR for the rest of the window — but cumulative cash is still below zero at month 24 because of the pre-launch burn. Peak requirement, not burn rate, is the number that matters.
B22: • Conservative is the honest downside: slower selling and higher churn. It does not recover the pre-launch spend inside 24 months — which is the real reason to raise or to pre-sell.
B23: • Aggressive is not a plan. It is what happens if the OTA-messaging wedge lands early.
B24: • In every scenario the constraint that binds first is founder selling time, then support hours — not capital.

Sheet 07_Sensitivity
B2: Sensitivity — where the model breaks
B3: The four assumptions that actually move the outcome: support load, churn, price and WhatsApp market.
B5: A. Gross margin vs support hours per property per month
B6: Support hrs / mo | C6: T1 ($299) | D6: T2 ($349) | E6: T3 ($449) | F6: T4 ($699) | G6: T5 ($1,199)
B7: 0.5 | C7: =('03_Unit_Economics'!E6-(('03_Unit_Economics'!H6+'03_Unit_Economics'!I6+'03_Unit_Economics'!J6+'03_Unit_Economics'!L6)+$B7*'01_Assumptions'!C6))/'03_Unit_Economics'!E6 -> 0.87706438 | D7: =('03_Unit_Economics'!E7-(('03_Unit_Economics'!H7+'03_Unit_Economics'!I7+'03_Unit_Economics'!J7+'03_Unit_Economics'!L7)+$B7*'01_Assumptions'!C6))/'03_Unit_Economics'!E7 -> 0.8901298 | E7: =('03_Unit_Economics'!E8-(('03_Unit_Economics'!H8+'03_Unit_Economics'!I8+'03_Unit_Economics'!J8+'03_Unit_Economics'!L8)+$B7*'01_Assumptions'!C6))/'03_Unit_Economics'!E8 -> 0.90764187 | F7: =('03_Unit_Economics'!E9-(('03_Unit_Economics'!H9+'03_Unit_Economics'!I9+'03_Unit_Economics'!J9+'03_Unit_Economics'!L9)+$B7*'01_Assumptions'!C6))/'03_Unit_Economics'!E9 -> 0.92516072 | G7: =('03_Unit_Economics'!E10-(('03_Unit_Economics'!H10+'03_Unit_Economics'!I10+'03_Unit_Economics'!J10+'03_Unit_Economics'!L10)+$B7*'01_Assumptions'!C6))/'03_Unit_Economics'!E10 -> 0.93036197
B8: 1 | C8: =('03_Unit_Economics'!E6-(('03_Unit_Economics'!H6+'03_Unit_Economics'!I6+'03_Unit_Economics'!J6+'03_Unit_Economics'!L6)+$B8*'01_Assumptions'!C6))/'03_Unit_Economics'!E6 -> 0.82355268 | D8: =('03_Unit_Economics'!E7-(('03_Unit_Economics'!H7+'03_Unit_Economics'!I7+'03_Unit_Economics'!J7+'03_Unit_Economics'!L7)+$B8*'01_Assumptions'!C6))/'03_Unit_Economics'!E7 -> 0.84428453 | E8: =('03_Unit_Economics'!E8-(('03_Unit_Economics'!H8+'03_Unit_Economics'!I8+'03_Unit_Economics'!J8+'03_Unit_Economics'!L8)+$B8*'01_Assumptions'!C6))/'03_Unit_Economics'!E8 -> 0.87200713 | F8: =('03_Unit_Economics'!E9-(('03_Unit_Economics'!H9+'03_Unit_Economics'!I9+'03_Unit_Economics'!J9+'03_Unit_Economics'!L9)+$B8*'01_Assumptions'!C6))/'03_Unit_Economics'!E9 -> 0.90227088 | G8: =('03_Unit_Economics'!E10-(('03_Unit_Economics'!H10+'03_Unit_Economics'!I10+'03_Unit_Economics'!J10+'03_Unit_Economics'!L10)+$B8*'01_Assumptions'!C6))/'03_Unit_Economics'!E10 -> 0.91701751
B9: 1.5 | C9: =('03_Unit_Economics'!E6-(('03_Unit_Economics'!H6+'03_Unit_Economics'!I6+'03_Unit_Economics'!J6+'03_Unit_Economics'!L6)+$B9*'01_Assumptions'!C6))/'03_Unit_Economics'!E6 -> 0.77004097 | D9: =('03_Unit_Economics'!E7-(('03_Unit_Economics'!H7+'03_Unit_Economics'!I7+'03_Unit_Economics'!J7+'03_Unit_Economics'!L7)+$B9*'01_Assumptions'!C6))/'03_Unit_Economics'!E7 -> 0.79843926 | E9: =('03_Unit_Economics'!E8-(('03_Unit_Economics'!H8+'03_Unit_Economics'!I8+'03_Unit_Economics'!J8+'03_Unit_Economics'!L8)+$B9*'01_Assumptions'!C6))/'03_Unit_Economics'!E8 -> 0.83637238 | F9: =('03_Unit_Economics'!E9-(('03_Unit_Economics'!H9+'03_Unit_Economics'!I9+'03_Unit_Economics'!J9+'03_Unit_Economics'!L9)+$B9*'01_Assumptions'!C6))/'03_Unit_Economics'!E9 -> 0.87938104 | G9: =('03_Unit_Economics'!E10-(('03_Unit_Economics'!H10+'03_Unit_Economics'!I10+'03_Unit_Economics'!J10+'03_Unit_Economics'!L10)+$B9*'01_Assumptions'!C6))/'03_Unit_Economics'!E10 -> 0.90367306
B10: 2 | C10: =('03_Unit_Economics'!E6-(('03_Unit_Economics'!H6+'03_Unit_Economics'!I6+'03_Unit_Economics'!J6+'03_Unit_Economics'!L6)+$B10*'01_Assumptions'!C6))/'03_Unit_Economics'!E6 -> 0.71652926 | D10: =('03_Unit_Economics'!E7-(('03_Unit_Economics'!H7+'03_Unit_Economics'!I7+'03_Unit_Economics'!J7+'03_Unit_Economics'!L7)+$B10*'01_Assumptions'!C6))/'03_Unit_Economics'!E7 -> 0.75259398 | E10: =('03_Unit_Economics'!E8-(('03_Unit_Economics'!H8+'03_Unit_Economics'!I8+'03_Unit_Economics'!J8+'03_Unit_Economics'!L8)+$B10*'01_Assumptions'!C6))/'03_Unit_Economics'!E8 -> 0.80073764 | F10: =('03_Unit_Economics'!E9-(('03_Unit_Economics'!H9+'03_Unit_Economics'!I9+'03_Unit_Economics'!J9+'03_Unit_Economics'!L9)+$B10*'01_Assumptions'!C6))/'03_Unit_Economics'!E9 -> 0.85649119 | G10: =('03_Unit_Economics'!E10-(('03_Unit_Economics'!H10+'03_Unit_Economics'!I10+'03_Unit_Economics'!J10+'03_Unit_Economics'!L10)+$B10*'01_Assumptions'!C6))/'03_Unit_Economics'!E10 -> 0.89032861
B11: 3 | C11: =('03_Unit_Economics'!E6-(('03_Unit_Economics'!H6+'03_Unit_Economics'!I6+'03_Unit_Economics'!J6+'03_Unit_Economics'!L6)+$B11*'01_Assumptions'!C6))/'03_Unit_Economics'!E6 -> 0.60950585 | D11: =('03_Unit_Economics'!E7-(('03_Unit_Economics'!H7+'03_Unit_Economics'!I7+'03_Unit_Economics'!J7+'03_Unit_Economics'!L7)+$B11*'01_Assumptions'!C6))/'03_Unit_Economics'!E7 -> 0.66090344 | E11: =('03_Unit_Economics'!E8-(('03_Unit_Economics'!H8+'03_Unit_Economics'!I8+'03_Unit_Economics'!J8+'03_Unit_Economics'!L8)+$B11*'01_Assumptions'!C6))/'03_Unit_Economics'!E8 -> 0.72946815 | F11: =('03_Unit_Economics'!E9-(('03_Unit_Economics'!H9+'03_Unit_Economics'!I9+'03_Unit_Economics'!J9+'03_Unit_Economics'!L9)+$B11*'01_Assumptions'!C6))/'03_Unit_Economics'!E9 -> 0.81071151 | G11: =('03_Unit_Economics'!E10-(('03_Unit_Economics'!H10+'03_Unit_Economics'!I10+'03_Unit_Economics'!J10+'03_Unit_Economics'!L10)+$B11*'01_Assumptions'!C6))/'03_Unit_Economics'!E10 -> 0.8636397
B12: 4 | C12: =('03_Unit_Economics'!E6-(('03_Unit_Economics'!H6+'03_Unit_Economics'!I6+'03_Unit_Economics'!J6+'03_Unit_Economics'!L6)+$B12*'01_Assumptions'!C6))/'03_Unit_Economics'!E6 -> 0.50248244 | D12: =('03_Unit_Economics'!E7-(('03_Unit_Economics'!H7+'03_Unit_Economics'!I7+'03_Unit_Economics'!J7+'03_Unit_Economics'!L7)+$B12*'01_Assumptions'!C6))/'03_Unit_Economics'!E7 -> 0.56921289 | E12: =('03_Unit_Economics'!E8-(('03_Unit_Economics'!H8+'03_Unit_Economics'!I8+'03_Unit_Economics'!J8+'03_Unit_Economics'!L8)+$B12*'01_Assumptions'!C6))/'03_Unit_Economics'!E8 -> 0.65819866 | F12: =('03_Unit_Economics'!E9-(('03_Unit_Economics'!H9+'03_Unit_Economics'!I9+'03_Unit_Economics'!J9+'03_Unit_Economics'!L9)+$B12*'01_Assumptions'!C6))/'03_Unit_Economics'!E9 -> 0.76493182 | G12: =('03_Unit_Economics'!E10-(('03_Unit_Economics'!H10+'03_Unit_Economics'!I10+'03_Unit_Economics'!J10+'03_Unit_Economics'!L10)+$B12*'01_Assumptions'!C6))/'03_Unit_Economics'!E10 -> 0.83695079
B14: B. LTV / CAC by monthly churn and property size
B15: Monthly churn | C15: T1 | D15: T2 | E15: T3 | F15: T4 | G15: T5
B16: 0.01 | C16: =('03_Unit_Economics'!N6/$B16)/'03_Unit_Economics'!X6 -> 27.715806 | D16: =('03_Unit_Economics'!N7/$B16)/'03_Unit_Economics'!X7 -> 32.383922 | E16: =('03_Unit_Economics'!N8/$B16)/'03_Unit_Economics'!X8 -> 42.081244 | F16: =('03_Unit_Economics'!N9/$B16)/'03_Unit_Economics'!X9 -> 66.876372 | G16: =('03_Unit_Economics'!N10/$B16)/'03_Unit_Economics'!X10 -> 115.76711
B17: 0.015 | C17: =('03_Unit_Economics'!N6/$B17)/'03_Unit_Economics'!X6 -> 18.477204 | D17: =('03_Unit_Economics'!N7/$B17)/'03_Unit_Economics'!X7 -> 21.589281 | E17: =('03_Unit_Economics'!N8/$B17)/'03_Unit_Economics'!X8 -> 28.054163 | F17: =('03_Unit_Economics'!N9/$B17)/'03_Unit_Economics'!X9 -> 44.584248 | G17: =('03_Unit_Economics'!N10/$B17)/'03_Unit_Economics'!X10 -> 77.178074
B18: 0.02 | C18: =('03_Unit_Economics'!N6/$B18)/'03_Unit_Economics'!X6 -> 13.857903 | D18: =('03_Unit_Economics'!N7/$B18)/'03_Unit_Economics'!X7 -> 16.191961 | E18: =('03_Unit_Economics'!N8/$B18)/'03_Unit_Economics'!X8 -> 21.040622 | F18: =('03_Unit_Economics'!N9/$B18)/'03_Unit_Economics'!X9 -> 33.438186 | G18: =('03_Unit_Economics'!N10/$B18)/'03_Unit_Economics'!X10 -> 57.883556
B19: 0.025 | C19: =('03_Unit_Economics'!N6/$B19)/'03_Unit_Economics'!X6 -> 11.086322 | D19: =('03_Unit_Economics'!N7/$B19)/'03_Unit_Economics'!X7 -> 12.953569 | E19: =('03_Unit_Economics'!N8/$B19)/'03_Unit_Economics'!X8 -> 16.832498 | F19: =('03_Unit_Economics'!N9/$B19)/'03_Unit_Economics'!X9 -> 26.750549 | G19: =('03_Unit_Economics'!N10/$B19)/'03_Unit_Economics'!X10 -> 46.306844
B20: 0.03 | C20: =('03_Unit_Economics'!N6/$B20)/'03_Unit_Economics'!X6 -> 9.2386019 | D20: =('03_Unit_Economics'!N7/$B20)/'03_Unit_Economics'!X7 -> 10.794641 | E20: =('03_Unit_Economics'!N8/$B20)/'03_Unit_Economics'!X8 -> 14.027081 | F20: =('03_Unit_Economics'!N9/$B20)/'03_Unit_Economics'!X9 -> 22.292124 | G20: =('03_Unit_Economics'!N10/$B20)/'03_Unit_Economics'!X10 -> 38.589037
B21: 0.04 | C21: =('03_Unit_Economics'!N6/$B21)/'03_Unit_Economics'!X6 -> 6.9289514 | D21: =('03_Unit_Economics'!N7/$B21)/'03_Unit_Economics'!X7 -> 8.0959806 | E21: =('03_Unit_Economics'!N8/$B21)/'03_Unit_Economics'!X8 -> 10.520311 | F21: =('03_Unit_Economics'!N9/$B21)/'03_Unit_Economics'!X9 -> 16.719093 | G21: =('03_Unit_Economics'!N10/$B21)/'03_Unit_Economics'!X10 -> 28.941778
B22: 0.05 | C22: =('03_Unit_Economics'!N6/$B22)/'03_Unit_Economics'!X6 -> 5.5431611 | D22: =('03_Unit_Economics'!N7/$B22)/'03_Unit_Economics'!X7 -> 6.4767844 | E22: =('03_Unit_Economics'!N8/$B22)/'03_Unit_Economics'!X8 -> 8.4162489 | F22: =('03_Unit_Economics'!N9/$B22)/'03_Unit_Economics'!X9 -> 13.375274 | G22: =('03_Unit_Economics'!N10/$B22)/'03_Unit_Economics'!X10 -> 23.153422
B23: 0.07 | C23: =('03_Unit_Economics'!N6/$B23)/'03_Unit_Economics'!X6 -> 3.9594008 | D23: =('03_Unit_Economics'!N7/$B23)/'03_Unit_Economics'!X7 -> 4.6262746 | E23: =('03_Unit_Economics'!N8/$B23)/'03_Unit_Economics'!X8 -> 6.0116063 | F23: =('03_Unit_Economics'!N9/$B23)/'03_Unit_Economics'!X9 -> 9.5537674 | G23: =('03_Unit_Economics'!N10/$B23)/'03_Unit_Economics'!X10 -> 16.538159
B25: C. How many properties cover fixed opex
B26: Blended gross profit / property / month | C26: ='01_Assumptions'!C43 -> 371.69179
B27: Fixed opex (base) | C27: ='01_Assumptions'!C36 -> 7200
B28: Properties needed to cover base opex | C28: =C27/C26 -> 19.370888
B29: Properties needed once step 1 triggers | C29: =(C27+'01_Assumptions'!C37)/C26 -> 29.056332
B30: Properties needed once step 2 triggers | C30: =(C27+2*'01_Assumptions'!C37)/C26 -> 38.741776
B31: MRR at step-1 breakeven | C31: =C29*'01_Assumptions'!C41 -> 12770.258
B32: Support hours / month at 1st step breakeven | C32: =C29*'03_Unit_Economics'!S12 -> 37.598894
B33: Support hours / month at 2nd step breakeven | C33: =C30*'03_Unit_Economics'!S12 -> 50.131858
B34: Support hours / week at 1st step breakeven | C34: =C32*12/52 -> 8.6766678
B35: D. WhatsApp cost per property per month — Mexico vs Germany
B36: Size | C36: Mexico | D36: Germany
B37: ='02_Property_Sizes'!B17 -> T1 | C37: ='04_Messaging_Costs'!C18 -> 0 | D37: ='04_Messaging_Costs'!F18 -> #VALUE!
B38: ='02_Property_Sizes'!B18 -> T2 | C38: ='04_Messaging_Costs'!C19 -> 0 | D38: ='04_Messaging_Costs'!F19 -> #VALUE!
B39: ='02_Property_Sizes'!B19 -> T3 | C39: ='04_Messaging_Costs'!C20 -> 0 | D39: ='04_Messaging_Costs'!F20 -> #VALUE!
B40: ='02_Property_Sizes'!B20 -> T4 | C40: ='04_Messaging_Costs'!C21 -> 14.924659 | D40: ='04_Messaging_Costs'!F21 -> #VALUE!
B41: ='02_Property_Sizes'!B21 -> T5 | C41: ='04_Messaging_Costs'!C22 -> 89.02725 | D41: ='04_Messaging_Costs'!F22 -> #VALUE!
B43: E. What breaks the model
B44: • Support above roughly 4 hours per property per month destroys T1 gross margin (see table A). This is precisely why the onboarding wizard, coverage score and weekly knowledge-gap email exist — they are support-cost reduction, not features.
B45: • At 5% monthly churn, LTV/CAC falls under 5x at every size (see B). Churn is the most dangerous variable and the one the weekly gap email improves fastest.
...

Sheet 08_Cash_Runway
B2: Cash requirement and runway
B3: Cumulative cash by scenario. Starts negative: pre-launch capital is spent before month 1.
B5: Month | C5: Conservative | D5: Base | E5: Aggressive
B6: 1 | C6: ='05_Ramp'!N12 -> -24200 | D6: ='05_Ramp'!N57 -> -24200 | E6: ='05_Ramp'!N102 -> -24200
B7: 2 | C7: ='05_Ramp'!N13 -> -30778.308 | D7: ='05_Ramp'!N58 -> -30778.308 | E7: ='05_Ramp'!N103 -> -30778.308
B8: 3 | C8: ='05_Ramp'!N14 -> -36984.925 | D8: ='05_Ramp'!N59 -> -36984.925 | E8: ='05_Ramp'!N104 -> -36984.925
B9: 4 | C9: ='05_Ramp'!N15 -> -42819.849 | D9: ='05_Ramp'!N60 -> -42819.849 | E9: ='05_Ramp'!N105 -> -42819.849
B10: 5 | C10: ='05_Ramp'!N16 -> -48283.082 | D10: ='05_Ramp'!N61 -> -48283.082 | E10: ='05_Ramp'!N106 -> -47661.39
B11: 6 | C11: ='05_Ramp'!N17 -> -53374.623 | D11: ='05_Ramp'!N62 -> -52752.931 | E11: ='05_Ramp'!N107 -> -51137.856
B12: 7 | C12: ='05_Ramp'!N18 -> -58094.472 | D12: ='05_Ramp'!N63 -> -56479.397 | E12: ='05_Ramp'!N108 -> -53499.246
B13: 8 | C13: ='05_Ramp'!N19 -> -62442.63 | D13: ='05_Ramp'!N64 -> -59462.479 | E13: ='05_Ramp'!N109 -> -54123.87
B14: 9 | C14: ='05_Ramp'!N20 -> -66419.096 | D14: ='05_Ramp'!N65 -> -61702.178 | E14: ='05_Ramp'!N110 -> -53261.726
B15: 10 | C15: ='05_Ramp'!N21 -> -70023.87 | D15: ='05_Ramp'!N66 -> -63198.493 | E15: ='05_Ramp'!N111 -> -50912.815
B16: 11 | C16: ='05_Ramp'!N22 -> -73256.952 | D16: ='05_Ramp'!N67 -> -63951.424 | E16: ='05_Ramp'!N112 -> -50677.136
B17: 12 | C17: ='05_Ramp'!N23 -> -76118.342 | D17: ='05_Ramp'!N68 -> -63960.972 | E17: ='05_Ramp'!N113 -> -48954.691
... B29: 24 | C29: ='05_Ramp'!N35 -> -74762.313 | D29: ='05_Ramp'!N80 -> -55823.285 | E29: ='05_Ramp'!N125 -> 60033.58
B31: Funding requirement | E31: If you want to avoid a raise
B32: Pre-launch capital (weeks 1-6) | C32: ='01_Assumptions'!C40 -> 17000 | E32: • Stay solo and unpaid for the first six months: the base case reaches breakeven without external capital, at the cost of speed.
B33: Base-case peak funding requirement | C33: =ABS('06_Scenarios'!D16) -> 63960.972 | E33: • Take three design partners with a $500 setup fee and a prepaid three-month subscription — roughly $4.5k of cash in week 6, which covers pre-launch burn.
B34: Conservative peak funding requirement | C34: =ABS('06_Scenarios'!C16) -> 80866.835 | E34: • Only raise once you have 10+ paying properties and a churn number you actually believe. Raising earlier prices a business you cannot yet describe.
B35: Recommended cash buffer (conservative peak + 30%) | C35: =C34*1.3 -> 105126.89
B36: Months of opex that buffer buys | C36: =C35/'01_Assumptions'!C36 -> 14.600956
B38: STAFFING REALITY CHECK
B39: Opex, solo build (model default) | C39: ='01_Assumptions'!C36 -> 7200
B40: Opex, 3-person build (editable estimate) | C40: 16700
B41: Blended gross profit / property / month | C41: ='01_Assumptions'!C43 -> 371.69179
B42: Properties needed to cover solo opex | C42: =C39/C41 -> 19.370888
B43: Properties needed to cover 3-person opex | C43: =C40/C41 -> 44.929699
B44: Extra burn to first profitable month (3-person) | C44: =(C40-C39)*'06_Scenarios'!D17 -> 123500
B45: Indicative peak requirement, 3-person build | C45: =C33+C44 -> 187460.97
B46: Hiring ahead of revenue raises the breakeven bar from ~19 to ~45 properties. That trade — speed for a 2.3x higher bar — is the single biggest decision in this plan.

Sheet 09_Market_Sizing
B2: Market sizing — Americas + Europe
B3: Hotel counts are cited public figures (2025-2026); the three filter percentages are estimates you should replace with your own pipeline data.
B5: Market | C5: Hotels (all) | D5: Independent % | E5: Target segment % | F5: Serviceable % | G5: Independent hotels | H5: Target-segment properties | I5: Serviceable properties
B6: Europe (28 countries) | C6: 158819 | D6: 0.74 | E6: 0.3 | F6: 0.4 | G6: =C6*D6 -> 117526.06 | H6: =G6*E6 -> 35257.818 | I6: =H6*F6 -> 14103.127 | J6: HOTREC 2026: 74% independent, median 39 rooms; 158,819 properties
B7: United States | C7: 50000 | D7: 0.4 | E7: 0.25 | F7: 0.35 | G7: =C7*D7 -> 20000 | H7: =G7*E7 -> 5000 | I7: =H7*F7 -> 1750 | J7: ~50k hotels/motels; ~40% independent (STR); luxury/upscale share lower
B8: Mexico | C8: 27948 | D8: 0.85 | E8: 0.35 | F8: 0.45 | G8: =C8*D8 -> 23755.8 | H8: =G8*E8 -> 8314.53 | I8: =H8*F8 -> 3741.5385 | J8: 27,948 establishments, +3.9% YoY (2025)
B9: Brazil | C9: 35000 | D9: 0.85 | E9: 0.25 | F9: 0.4 | G9: =C9*D9 -> 29750 | H9: =G9*E9 -> 7437.5 | I9: =H9*F9 -> 2975 | J9: Registered hotel businesses; treat as low-confidence, wide interval
B10: Canada | C10: 7560 | D10: 0.6 | E10: 0.3 | F10: 0.35 | G10: =C10*D10 -> 4536 | H10: =G10*E10 -> 1360.8 | I10: =H10*F10 -> 476.28 | J10: ~7,560 hotels / 466,850 rooms (Horwath 2026)
B11: TOTAL | C11: =SUM(C6:C10) -> 279327 | G11: =SUM(G6:G10) -> 195567.86 | H11: =SUM(H6:H10) -> 57370.648 | I11: =SUM(I6:I10) -> 23045.946
B13: Revenue pool and penetration
B14: Metric | C14: Value | D14: Note
B15: Blended ARPU $/month | C15: ='01_Assumptions'!C41 -> 439.5 | D15: Mix-weighted from 02_Property_Sizes
B16: Serviceable ARR pool | C16: =I11*C15*12 -> 1.2154432e+08 | D16: What the whole serviceable footprint is worth at current pricing
B17: Properties in base case, month 24 | C17: ='06_Scenarios'!D7 -> 31 | D17: From 05_Ramp
B18: Base case as % of serviceable | C18: =C17/I11 -> 0.001345139 | D18: The market is not the constraint
B19: Properties for 0.5% penetration | C19: =I11*0.005 -> 115.22973
B20: ARR at 0.5% penetration | C20: =C19*C15*12 -> 607721.59
B21: Properties for 1% penetration | C21: =I11*0.01 -> 230.45946
B22: ARR at 1% penetration | C22: =C21*C15*12 -> 1215443.2
B23: Properties for 2% penetration | C23: =I11*0.02 -> 460.91891
B24: ARR at 2% penetration | C24: =C23*C15*12 -> 2430886.4
B26: Channel fit by market — this drives the channel roadmap, not preference
B27: Market | C27: WhatsApp penetration | D27: Primary guest channel | E27: Secondary | F27: Build implication
B28: Mexico | C28: ~90% | D28: WhatsApp | E28: Web + QR | F28: WhatsApp is v1.1, not optional
B29: Brazil | C29: ~98% | D29: WhatsApp | E29: Web + QR | F29: Highest WhatsApp dependence in the footprint
B30: Spain | C30: ~90% | D30: WhatsApp | E30: Web + QR | F30: Same language and channel as Mexico: one beachhead, two continents
B31: Germany / Italy | C31: ~85-90% | D31: WhatsApp | E31: Web + QR | F31: High per-message cost (DE 6.5x MX) + German/Italian language
B32: United States | C32: ~25-30% | D32: Web + QR | E32: SMS / RCS | F32: DO NOT sell the US on WhatsApp alone — SMS/RCS is a separate channel build
B33: Canada | C33: ~45% | D33: Web + QR | E33: SMS | F33: Similar to US but WhatsApp stronger
B35: Compliance footprint (all in force as of Oct 2026)
B36: Regime | C36: Applies to | D36: Requirement
B37: EU AI Act Art. 50 | C37: Any AI system whose output reaches EU users, even from outside the EU | D37: Disclose AI at the start of the interaction; machine-readable marking of generated output. In force 2 Aug 2026; fines to EUR 15m or 3% of worldwide turnover
B38: GDPR | C38: EU/EEA guest data | D38: Lawful basis, DPIA, DPA, EU data residency option, retention limits, erasure
B39: LGPD | C39: Brazil | D39: Similar to GDPR; legal basis and DPO expectations
B40: LFPDPPP | C40: Mexico | D40: Privacy notice, consent, data-subject rights
B41: VAT / OSS | C41: Selling B2B SaaS into the EU | D41: VAT registration or merchant-of-record; reverse-charge invoicing for B2B
B43: Read this before expanding: the footprint is 57k target properties and the base case needs 31 of them (0.13%). Market breadth is not your constraint — compliance, language, support time zones and sales are. Build global-ready, sell one beachhead at a time.
